{"url": "https://www.reddit.com/r/learnprogramming/comments/99zyhj/aws_lambda_internal_server_error/", "text": "I'm feeling a little dumb here. I have a test function:\n\n    exports.handler = async (event, context, callback) => {\n        callback(null, \"Some message.\");\n    };\n\nI have saved and published it. When I test it I get `Response:\n\"Some message.\"`. But when I navigate to the API endpoint I get `{\"message\": \"Internal server error\"}`.\n\nThe endpoint is marked as `Authorization: NONE   Method: ANY`\n\nWhat am I missing here?", "score": 1, "comments": [{"body": "Look up the error in CloudWatch.\n\n[https://docs.aws.amazon.com/lambda/latest/dg/monitoring-functions-logs.html](https://docs.aws.amazon.com/lambda/latest/dg/monitoring-functions-logs.html)", "id": "e4ro7fs", "replies": [{"body": "This is all I get in the logs\n\n    START RequestId: 56... Version: $LATEST\n    END RequestId: 56...\n    REPORT RequestId: 56...\tDuration: 8.67 ms\tBilled Duration: 100 ms Memory Size: 128 MB\tMax Memory Used: 46 MB\n\nAnd no errors in the monitor at a glance.", "id": "e4roemf", "replies": []}]}, {"body": "Fixed it by returning a stringified object inside of a return object... Is this \"the way\" to do this?\n\n    exports.handler = async (event, context, callback) => {\n        callback(null, { \"statusCode\" : 200, \"body\" : JSON.stringify({\"one\":\"two\"})});\n    };", "id": "e4rpbyo", "replies": []}], "title": "AWS lambda \"Internal server error\""}